================================================================================
Image Processing System Test Report
Generated: 2025-03-03 06:00:55
================================================================================


UNIT_TESTS
----------
Duration: 161.09 seconds
Status: FAILED

Standard Output:
============================= test session starts =============================
platform win32 -- Python 3.13.2, pytest-8.3.4, pluggy-1.5.0 -- C:\Users\Noah\AppData\Local\Programs\Python\Python313\python.exe
cachedir: .pytest_cache
PyQt6 6.8.1 -- Qt runtime 6.8.2 -- Qt compiled 6.8.2
rootdir: C:\Users\Noah\Desktop\Ebay Auto
configfile: pytest.ini
testpaths: tests
plugins: anyio-4.8.0, asyncio-0.25.3, cov-6.0.0, mock-3.14.0, qt-4.4.0
asyncio: mode=Mode.AUTO, asyncio_default_fixture_loop_scope=function
collecting ... collected 73 items / 50 deselected / 23 selected

tests/test_opencv_utils.py::test_load_image_success PASSED               [  4%]
tests/test_opencv_utils.py::test_load_image_nonexistent 
-------------------------------- live log call --------------------------------
2025-03-03 05:58:19 [   ERROR] Failed to load image: nonexistent.jpg (opencv_utils.py:26)
PASSED                                                                   [  8%]
tests/test_opencv_utils.py::test_convert_to_grayscale_rgb PASSED         [ 13%]
tests/test_opencv_utils.py::test_convert_to_grayscale_already_gray PASSED [ 17%]
tests/test_opencv_utils.py::test_resize_image_larger PASSED              [ 21%]
tests/test_opencv_utils.py::test_resize_image_smaller PASSED             [ 26%]
tests/test_opencv_utils.py::test_enhance_contrast PASSED                 [ 30%]
tests/test_opencv_utils.py::test_denoise_image FAILED                    [ 34%]
tests/test_opencv_utils.py::test_preprocess_image_complete PASSED        [ 39%]
tests/test_opencv_utils.py::test_normalize_image PASSED                  [ 43%]
tests/test_opencv_utils.py::test_extract_text_regions PASSED             [ 47%]
tests/test_opencv_utils.py::test_error_handling 
-------------------------------- live log call --------------------------------
2025-03-03 05:58:20 [   ERROR] Contrast enhancement error: OpenCV(4.11.0) D:\a\opencv-python\opencv-python\opencv\modules\imgproc\src\clahe.cpp:353: error: (-215:Assertion failed) _src.type() == CV_8UC1 || _src.type() == CV_16UC1 in function '`anonymous-namespace'::CLAHE_Impl::apply'
 (opencv_utils.py:76)
2025-03-03 05:58:20 [   ERROR] Normalization error: divide by zero encountered in divide (opencv_utils.py:175)
PASSED                                                                   [ 52%]
tests/test_tmdb.py::test_search_movies PASSED                            [ 56%]
tests/test_tmdb.py::test_get_movie PASSED                                [ 60%]
tests/test_tmdb.py::test_invalid_movie_search PASSED                     [ 65%]
tests/test_tmdb.py::test_invalid_movie_id PASSED                         [ 69%]
tests/test_tmdb.py::test_tmdb_client_no_api_key PASSED                   [ 73%]
tests/test_vision_processor.py::test_process_image_progress_tracking 
------------------------------- live log setup --------------------------------
2025-03-03 05:58:22 [ WARNING] Error checking models: HTTPConnectionPool(host='127.0.0.1', port=1234): Max retries exceeded with url: /v1/models (Caused by ConnectTimeoutError(<urllib3.connection.HTTPConnection object at 0x000002CBBF6AC830>, 'Connection to 127.0.0.1 timed out. (connect timeout=2)')) (vhs_vision.py:64)
2025-03-03 05:58:22 [ WARNING] Discogs API not available - will rely on vision only (processor.py:39)
-------------------------------- live log call --------------------------------
2025-03-03 05:58:22 [    INFO] Processing image: C:\Users\Noah\AppData\Local\Temp\pytest-of-Noah\pytest-365\test_process_image_progress_tr0\test_vhs.jpg (processor.py:52)
2025-03-03 05:58:27 [   ERROR] API request failed: HTTPConnectionPool(host='127.0.0.1', port=1234): Max retries exceeded with url: /v1/chat/completions (Caused by NewConnectionError('<urllib3.connection.HTTPConnection object at 0x000002CBBF680690>: Failed to establish a new connection: [WinError 10061] No connection could be made because the target machine actively refused it')) (vhs_vision.py:212)
2025-03-03 05:58:27 [   ERROR] API error processing region: cannot access local variable 'response' where it is not associated with a value (vhs_vision.py:246)
2025-03-03 05:58:32 [   ERROR] API request failed: HTTPConnectionPool(host='127.0.0.1', port=1234): Max retries exceeded with url: /v1/chat/completions (Caused by NewConnectionError('<urllib3.connection.HTTPConnection object at 0x000002CBBF58F360>: Failed to establish a new connection: [WinError 10061] No connection could be made because the target machine actively refused it')) (vhs_vision.py:212)
2025-03-03 05:58:32 [   ERROR] API error processing region: cannot access local variable 'response' where it is not associated with a value (vhs_vision.py:246)
2025-03-03 05:58:37 [   ERROR] API request failed: HTTPConnectionPool(host='127.0.0.1', port=1234): Max retries exceeded with url: /v1/chat/completions (Caused by NewConnectionError('<urllib3.connection.HTTPConnection object at 0x000002CBC069D150>: Failed to establish a new connection: [WinError 10061] No connection could be made because the target machine actively refused it')) (vhs_vision.py:212)
2025-03-03 05:58:37 [   ERROR] API error processing region: cannot access local variable 'response' where it is not associated with a value (vhs_vision.py:246)
2025-03-03 05:58:42 [   ERROR] API request failed: HTTPConnectionPool(host='127.0.0.1', port=1234): Max retries exceeded with url: /v1/chat/completions (Caused by NewConnectionError('<urllib3.connection.HTTPConnection object at 0x000002CBC069DD00>: Failed to establish a new connection: [WinError 10061] No connection could be made because the target machine actively refused it')) (vhs_vision.py:212)
2025-03-03 05:58:42 [   ERROR] API error processing region: cannot access local variable 'response' where it is not associated with a value (vhs_vision.py:246)
2025-03-03 05:58:47 [   ERROR] API request failed: HTTPConnectionPool(host='127.0.0.1', port=1234): Max retries exceeded with url: /v1/chat/completions (Caused by NewConnectionError('<urllib3.connection.HTTPConnection object at 0x000002CBBF53FBD0>: Failed to establish a new connection: [WinError 10061] No connection could be made because the target machine actively refused it')) (vhs_vision.py:212)
2025-03-03 05:58:47 [   ERROR] API error processing region: cannot access local variable 'response' where it is not associated with a value (vhs_vision.py:246)
2025-03-03 05:58:52 [   ERROR] API request failed: HTTPConnectionPool(host='127.0.0.1', port=1234): Max retries exceeded with url: /v1/chat/completions (Caused by NewConnectionError('<urllib3.connection.HTTPConnection object at 0x000002CBBF53ECF0>: Failed to establish a new connection: [WinError 10061] No connection could be made because the target machine actively refused it')) (vhs_vision.py:212)
2025-03-03 05:58:52 [   ERROR] API error processing region: cannot access local variable 'response' where it is not associated with a value (vhs_vision.py:246)
2025-03-03 05:58:57 [   ERROR] API request failed: HTTPConnectionPool(host='127.0.0.1', port=1234): Max retries exceeded with url: /v1/chat/completions (Caused by NewConnectionError('<urllib3.connection.HTTPConnection object at 0x000002CBBF53F460>: Failed to establish a new connection: [WinError 10061] No connection could be made because the target machine actively refused it')) (vhs_vision.py:212)
2025-03-03 05:58:57 [   ERROR] API error processing region: cannot access local variable 'response' where it is not associated with a value (vhs_vision.py:246)
PASSED                                                                   [ 78%]
tests/test_vision_processor.py::test_process_image_handles_missing_callback 
------------------------------- live log setup --------------------------------
2025-03-03 05:59:00 [ WARNING] Error checking models: HTTPConnectionPool(host='127.0.0.1', port=1234): Max retries exceeded with url: /v1/models (Caused by ConnectTimeoutError(<urllib3.connection.HTTPConnection object at 0x000002CBBF53F8A0>, 'Connection to 127.0.0.1 timed out. (connect timeout=2)')) (vhs_vision.py:64)
2025-03-03 05:59:00 [ WARNING] Discogs API not available - will rely on vision only (processor.py:39)
-------------------------------- live log call --------------------------------
2025-03-03 05:59:00 [    INFO] Processing image: C:\Users\Noah\AppData\Local\Temp\pytest-of-Noah\pytest-365\test_process_image_handles_mis0\test_vhs.jpg (processor.py:52)
2025-03-03 05:59:05 [   ERROR] API request failed: HTTPConnectionPool(host='127.0.0.1', port=1234): Max retries exceeded with url: /v1/chat/completions (Caused by NewConnectionError('<urllib3.connection.HTTPConnection object at 0x000002CBC069E030>: Failed to establish a new connection: [WinError 10061] No connection could be made because the target machine actively refused it')) (vhs_vision.py:212)
2025-03-03 05:59:05 [   ERROR] API error processing region: cannot access local variable 'response' where it is not associated with a value (vhs_vision.py:246)
2025-03-03 05:59:10 [   ERROR] API request failed: HTTPConnectionPool(host='127.0.0.1', port=1234): Max retries exceeded with url: /v1/chat/completions (Caused by NewConnectionError('<urllib3.connection.HTTPConnection object at 0x000002CBC069D9D0>: Failed to establish a new connection: [WinError 10061] No connection could be made because the target machine actively refused it')) (vhs_vision.py:212)
2025-03-03 05:59:10 [   ERROR] API error processing region: cannot access local variable 'response' where it is not associated with a value (vhs_vision.py:246)
2025-03-03 05:59:15 [   ERROR] API request failed: HTTPConnectionPool(host='127.0.0.1', port=1234): Max retries exceeded with url: /v1/chat/completions (Caused by NewConnectionError('<urllib3.connection.HTTPConnection object at 0x000002CBC069D260>: Failed to establish a new connection: [WinError 10061] No connection could be made because the target machine actively refused it')) (vhs_vision.py:212)
2025-03-03 05:59:15 [   ERROR] API error processing region: cannot access local variable 'response' where it is not associated with a value (vhs_vision.py:246)
2025-03-03 05:59:20 [   ERROR] API request failed: HTTPConnectionPool(host='127.0.0.1', port=1234): Max retries exceeded with url: /v1/chat/completions (Caused by NewConnectionError('<urllib3.connection.HTTPConnection object at 0x000002CBBF53F790>: Failed to establish a new connection: [WinError 10061] No connection could be made because the target machine actively refused it')) (vhs_vision.py:212)
2025-03-03 05:59:20 [   ERROR] API error processing region: cannot access local variable 'response' where it is not associated with a value (vhs_vision.py:246)
2025-03-03 05:59:25 [   ERROR] API request failed: HTTPConnectionPool(host='127.0.0.1', port=1234): Max retries exceeded with url: /v1/chat/completions (Caused by NewConnectionError('<urllib3.connection.HTTPConnection object at 0x000002CBBF53F020>: Failed to establish a new connection: [WinError 10061] No connection could be made because the target machine actively refused it')) (vhs_vision.py:212)
2025-03-03 05:59:25 [   ERROR] API error processing region: cannot access local variable 'response' where it is not associated with a value (vhs_vision.py:246)
2025-03-03 05:59:30 [   ERROR] API request failed: HTTPConnectionPool(host='127.0.0.1', port=1234): Max retries exceeded with url: /v1/chat/completions (Caused by NewConnectionError('<urllib3.connection.HTTPConnection object at 0x000002CBBF53FCE0>: Failed to establish a new connection: [WinError 10061] No connection could be made because the target machine actively refused it')) (vhs_vision.py:212)
2025-03-03 05:59:30 [   ERROR] API error processing region: cannot access local variable 'response' where it is not associated with a value (vhs_vision.py:246)
2025-03-03 05:59:35 [   ERROR] API request failed: HTTPConnectionPool(host='127.0.0.1', port=1234): Max retries exceeded with url: /v1/chat/completions (Caused by NewConnectionError('<urllib3.connection.HTTPConnection object at 0x000002CBC069D150>: Failed to establish a new connection: [WinError 10061] No connection could be made because the target machine actively refused it')) (vhs_vision.py:212)
2025-03-03 05:59:35 [   ERROR] API error processing region: cannot access local variable 'response' where it is not associated with a value (vhs_vision.py:246)
PASSED                                                                   [ 82%]
tests/test_vision_processor.py::test_process_image_error_handling 
------------------------------- live log setup --------------------------------
2025-03-03 05:59:37 [ WARNING] Error checking models: HTTPConnectionPool(host='127.0.0.1', port=1234): Max retries exceeded with url: /v1/models (Caused by ConnectTimeoutError(<urllib3.connection.HTTPConnection object at 0x000002CBBF53F680>, 'Connection to 127.0.0.1 timed out. (connect timeout=2)')) (vhs_vision.py:64)
2025-03-03 05:59:37 [ WARNING] Discogs API not available - will rely on vision only (processor.py:39)
-------------------------------- live log call --------------------------------
2025-03-03 05:59:37 [    INFO] Processing image: nonexistent.jpg (processor.py:52)
2025-03-03 05:59:37 [   ERROR] Failed to load image: nonexistent.jpg (opencv_utils.py:26)
PASSED                                                                   [ 86%]
tests/test_vision_processor.py::test_process_image_with_invalid_image 
------------------------------- live log setup --------------------------------
2025-03-03 05:59:39 [ WARNING] Error checking models: HTTPConnectionPool(host='127.0.0.1', port=1234): Max retries exceeded with url: /v1/models (Caused by ConnectTimeoutError(<urllib3.connection.HTTPConnection object at 0x000002CBC069D370>, 'Connection to 127.0.0.1 timed out. (connect timeout=2)')) (vhs_vision.py:64)
2025-03-03 05:59:39 [ WARNING] Discogs API not available - will rely on vision only (processor.py:39)
-------------------------------- live log call --------------------------------
2025-03-03 05:59:39 [    INFO] Processing image: C:\Users\Noah\AppData\Local\Temp\pytest-of-Noah\pytest-365\test_process_image_with_invali0\invalid.jpg (processor.py:52)
2025-03-03 05:59:39 [   ERROR] Failed to load image: C:\Users\Noah\AppData\Local\Temp\pytest-of-Noah\pytest-365\test_process_image_with_invali0\invalid.jpg (opencv_utils.py:26)
PASSED                                                                   [ 91%]
tests/test_vision_processor.py::test_process_image_success_validation 
------------------------------- live log setup --------------------------------
2025-03-03 05:59:41 [ WARNING] Error checking models: HTTPConnectionPool(host='127.0.0.1', port=1234): Max retries exceeded with url: /v1/models (Caused by ConnectTimeoutError(<urllib3.connection.HTTPConnection object at 0x000002CBC069C7C0>, 'Connection to 127.0.0.1 timed out. (connect timeout=2)')) (vhs_vision.py:64)
2025-03-03 05:59:41 [ WARNING] Discogs API not available - will rely on vision only (processor.py:39)
-------------------------------- live log call --------------------------------
2025-03-03 05:59:41 [    INFO] Processing image: C:\Users\Noah\AppData\Local\Temp\pytest-of-Noah\pytest-365\test_process_image_success_val0\test_vhs.jpg (processor.py:52)
2025-03-03 05:59:47 [   ERROR] API request failed: HTTPConnectionPool(host='127.0.0.1', port=1234): Max retries exceeded with url: /v1/chat/completions (Caused by NewConnectionError('<urllib3.connection.HTTPConnection object at 0x000002CBC069DF20>: Failed to establish a new connection: [WinError 10061] No connection could be made because the target machine actively refused it')) (vhs_vision.py:212)
2025-03-03 05:59:47 [   ERROR] API error processing region: cannot access local variable 'response' where it is not associated with a value (vhs_vision.py:246)
2025-03-03 05:59:52 [   ERROR] API request failed: HTTPConnectionPool(host='127.0.0.1', port=1234): Max retries exceeded with url: /v1/chat/completions (Caused by NewConnectionError('<urllib3.connection.HTTPConnection object at 0x000002CBBF53F680>: Failed to establish a new connection: [WinError 10061] No connection could be made because the target machine actively refused it')) (vhs_vision.py:212)
2025-03-03 05:59:52 [   ERROR] API error processing region: cannot access local variable 'response' where it is not associated with a value (vhs_vision.py:246)
2025-03-03 05:59:57 [   ERROR] API request failed: HTTPConnectionPool(host='127.0.0.1', port=1234): Max retries exceeded with url: /v1/chat/completions (Caused by NewConnectionError('<urllib3.connection.HTTPConnection object at 0x000002CBBF53FBD0>: Failed to establish a new connection: [WinError 10061] No connection could be made because the target machine actively refused it')) (vhs_vision.py:212)
2025-03-03 05:59:57 [   ERROR] API error processing region: cannot access local variable 'response' where it is not associated with a value (vhs_vision.py:246)
2025-03-03 06:00:02 [   ERROR] API request failed: HTTPConnectionPool(host='127.0.0.1', port=1234): Max retries exceeded with url: /v1/chat/completions (Caused by NewConnectionError('<urllib3.connection.HTTPConnection object at 0x000002CBBF53EBE0>: Failed to establish a new connection: [WinError 10061] No connection could be made because the target machine actively refused it')) (vhs_vision.py:212)
2025-03-03 06:00:02 [   ERROR] API error processing region: cannot access local variable 'response' where it is not associated with a value (vhs_vision.py:246)
2025-03-03 06:00:07 [   ERROR] API request failed: HTTPConnectionPool(host='127.0.0.1', port=1234): Max retries exceeded with url: /v1/chat/completions (Caused by NewConnectionError('<urllib3.connection.HTTPConnection object at 0x000002CBC069CD10>: Failed to establish a new connection: [WinError 10061] No connection could be made because the target machine actively refused it')) (vhs_vision.py:212)
2025-03-03 06:00:07 [   ERROR] API error processing region: cannot access local variable 'response' where it is not associated with a value (vhs_vision.py:246)
2025-03-03 06:00:12 [   ERROR] API request failed: HTTPConnectionPool(host='127.0.0.1', port=1234): Max retries exceeded with url: /v1/chat/completions (Caused by NewConnectionError('<urllib3.connection.HTTPConnection object at 0x000002CBC069C8D0>: Failed to establish a new connection: [WinError 10061] No connection could be made because the target machine actively refused it')) (vhs_vision.py:212)
2025-03-03 06:00:12 [   ERROR] API error processing region: cannot access local variable 'response' where it is not associated with a value (vhs_vision.py:246)
2025-03-03 06:00:17 [   ERROR] API request failed: HTTPConnectionPool(host='127.0.0.1', port=1234): Max retries exceeded with url: /v1/chat/completions (Caused by NewConnectionError('<urllib3.connection.HTTPConnection object at 0x000002CBC069CF30>: Failed to establish a new connection: [WinError 10061] No connection could be made because the target machine actively refused it')) (vhs_vision.py:212)
2025-03-03 06:00:17 [   ERROR] API error processing region: cannot access local variable 'response' where it is not associated with a value (vhs_vision.py:246)
PASSED                                                                   [ 95%]
tests/test_vision_processor.py::test_api_backup_triggering 
------------------------------- live log setup --------------------------------
2025-03-03 06:00:19 [ WARNING] Error checking models: HTTPConnectionPool(host='127.0.0.1', port=1234): Max retries exceeded with url: /v1/models (Caused by ConnectTimeoutError(<urllib3.connection.HTTPConnection object at 0x000002CBBF53FAC0>, 'Connection to 127.0.0.1 timed out. (connect timeout=2)')) (vhs_vision.py:64)
2025-03-03 06:00:19 [ WARNING] Discogs API not available - will rely on vision only (processor.py:39)
-------------------------------- live log call --------------------------------
2025-03-03 06:00:19 [    INFO] Processing image: C:\Users\Noah\AppData\Local\Temp\pytest-of-Noah\pytest-365\test_api_backup_triggering0\test_vhs.jpg (processor.py:52)
2025-03-03 06:00:24 [   ERROR] API request failed: HTTPConnectionPool(host='127.0.0.1', port=1234): Max retries exceeded with url: /v1/chat/completions (Caused by NewConnectionError('<urllib3.connection.HTTPConnection object at 0x000002CBBF53FDF0>: Failed to establish a new connection: [WinError 10061] No connection could be made because the target machine actively refused it')) (vhs_vision.py:212)
2025-03-03 06:00:24 [   ERROR] API error processing region: cannot access local variable 'response' where it is not associated with a value (vhs_vision.py:246)
2025-03-03 06:00:29 [   ERROR] API request failed: HTTPConnectionPool(host='127.0.0.1', port=1234): Max retries exceeded with url: /v1/chat/completions (Caused by NewConnectionError('<urllib3.connection.HTTPConnection object at 0x000002CBBF53F790>: Failed to establish a new connection: [WinError 10061] No connection could be made because the target machine actively refused it')) (vhs_vision.py:212)
2025-03-03 06:00:29 [   ERROR] API error processing region: cannot access local variable 'response' where it is not associated with a value (vhs_vision.py:246)
2025-03-03 06:00:35 [   ERROR] API request failed: HTTPConnectionPool(host='127.0.0.1', port=1234): Max retries exceeded with url: /v1/chat/completions (Caused by NewConnectionError('<urllib3.connection.HTTPConnection object at 0x000002CBBF53F9B0>: Failed to establish a new connection: [WinError 10061] No connection could be made because the target machine actively refused it')) (vhs_vision.py:212)
2025-03-03 06:00:35 [   ERROR] API error processing region: cannot access local variable 'response' where it is not associated with a value (vhs_vision.py:246)
2025-03-03 06:00:40 [   ERROR] API request failed: HTTPConnectionPool(host='127.0.0.1', port=1234): Max retries exceeded with url: /v1/chat/completions (Caused by NewConnectionError('<urllib3.connection.HTTPConnection object at 0x000002CBC069D040>: Failed to establish a new connection: [WinError 10061] No connection could be made because the target machine actively refused it')) (vhs_vision.py:212)
2025-03-03 06:00:40 [   ERROR] API error processing region: cannot access local variable 'response' where it is not associated with a value (vhs_vision.py:246)
2025-03-03 06:00:45 [   ERROR] API request failed: HTTPConnectionPool(host='127.0.0.1', port=1234): Max retries exceeded with url: /v1/chat/completions (Caused by NewConnectionError('<urllib3.connection.HTTPConnection object at 0x000002CBC069C7C0>: Failed to establish a new connection: [WinError 10061] No connection could be made because the target machine actively refused it')) (vhs_vision.py:212)
2025-03-03 06:00:45 [   ERROR] API error processing region: cannot access local variable 'response' where it is not associated with a value (vhs_vision.py:246)
2025-03-03 06:00:50 [   ERROR] API request failed: HTTPConnectionPool(host='127.0.0.1', port=1234): Max retries exceeded with url: /v1/chat/completions (Caused by NewConnectionError('<urllib3.connection.HTTPConnection object at 0x000002CBC069D150>: Failed to establish a new connection: [WinError 10061] No connection could be made because the target machine actively refused it')) (vhs_vision.py:212)
2025-03-03 06:00:50 [   ERROR] API error processing region: cannot access local variable 'response' where it is not associated with a value (vhs_vision.py:246)
2025-03-03 06:00:55 [   ERROR] API request failed: HTTPConnectionPool(host='127.0.0.1', port=1234): Max retries exceeded with url: /v1/chat/completions (Caused by NewConnectionError('<urllib3.connection.HTTPConnection object at 0x000002CBC069C490>: Failed to establish a new connection: [WinError 10061] No connection could be made because the target machine actively refused it')) (vhs_vision.py:212)
2025-03-03 06:00:55 [   ERROR] API error processing region: cannot access local variable 'response' where it is not associated with a value (vhs_vision.py:246)
FAILED                                                                   [100%]

================================== FAILURES ===================================
_____________________________ test_denoise_image ______________________________

noisy_image = array([[ 19, 254,  23, ...,  14,   0, 239],
       [  8, 232, 249, ...,  45, 212, 211],
       [245, 243, 210, ..., 24...,  23, 249, 233],
       [237, 208, 255, ...,   2,  36,   8],
       [249,   2, 223, ...,   1,  21, 237]], dtype=uint8)

    @pytest.mark.unit
    def test_denoise_image(noisy_image):
        """Test image denoising."""
        denoised = opencv_utils.denoise_image(noisy_image)
    
        # Denoised image should have less variation in flat areas
        roi_noisy = noisy_image[30:70, 30:70]  # Center region
        roi_denoised = denoised[30:70, 30:70]
>       assert np.std(roi_denoised) < np.std(roi_noisy)
E       assert 0.0 < 0.0
E        +  where 0.0 = <function std at 0x000002CBBC2DE1F0>(array([[255, 255, 255, ..., 255, 255, 255],\n       [255, 255, 255, ..., 255, 255, 255],\n       [255, 255, 255, ..., 255, 255, 255],\n       ...,\n       [255, 255, 255, ..., 255, 255, 255],\n       [255, 255, 255, ..., 255, 255, 255],\n       [255, 255, 255, ..., 255, 255, 255]], dtype=uint8))
E        +    where <function std at 0x000002CBBC2DE1F0> = np.std
E        +  and   0.0 = <function std at 0x000002CBBC2DE1F0>(array([[255, 255, 255, ..., 255, 255, 255],\n       [255, 255, 255, ..., 255, 255, 255],\n       [255, 255, 255, ..., 255, 255, 255],\n       ...,\n       [255, 255, 255, ..., 255, 255, 255],\n       [255, 255, 255, ..., 255, 255, 255],\n       [255, 255, 255, ..., 255, 255, 255]], dtype=uint8))
E        +    where <function std at 0x000002CBBC2DE1F0> = np.std

tests\test_opencv_utils.py:101: AssertionError
_________________________ test_api_backup_triggering __________________________

processor = <src.vision.processor.VisionProcessor object at 0x000002CBBF5BEC30>
sample_vhs_image = 'C:\\Users\\Noah\\AppData\\Local\\Temp\\pytest-of-Noah\\pytest-365\\test_api_backup_triggering0\\test_vhs.jpg'
monkeypatch = <_pytest.monkeypatch.MonkeyPatch object at 0x000002CBBF58E190>

    @pytest.mark.unit
    def test_api_backup_triggering(processor, sample_vhs_image, monkeypatch):
        """Test that API backup is triggered for low confidence results."""
        # Mock the _needs_api_backup method to always return True
        monkeypatch.setattr(processor, "_needs_api_backup", lambda x: True)
    
        # Create a mock for the API call
        mock_api_result = {
            "title": "API Title",
            "year": "2024",
            "runtime": "120",
            "confidence": 0.85
        }
        monkeypatch.setattr(
            "src.enrichment.api_client.search_movie_details",
            lambda x: mock_api_result
        )
    
        results = processor.process_image(sample_vhs_image)
    
        # Verify that API data was used
>       assert any(source == "api" for source in results.get("source", {}).values())
E       assert False
E        +  where False = any(<generator object test_api_backup_triggering.<locals>.<genexpr> at 0x000002CBC069AA80>)

tests\test_vision_processor.py:157: AssertionError
----------------------------- Captured log setup ------------------------------
WARNING  src.vision.vhs_vision:vhs_vision.py:64 Error checking models: HTTPConnectionPool(host='127.0.0.1', port=1234): Max retries exceeded with url: /v1/models (Caused by ConnectTimeoutError(<urllib3.connection.HTTPConnection object at 0x000002CBBF53FAC0>, 'Connection to 127.0.0.1 timed out. (connect timeout=2)'))
WARNING  src.vision.processor:processor.py:39 Discogs API not available - will rely on vision only
------------------------------ Captured log call ------------------------------
INFO     src.vision.processor:processor.py:52 Processing image: C:\Users\Noah\AppData\Local\Temp\pytest-of-Noah\pytest-365\test_api_backup_triggering0\test_vhs.jpg
ERROR    src.vision.vhs_vision:vhs_vision.py:212 API request failed: HTTPConnectionPool(host='127.0.0.1', port=1234): Max retries exceeded with url: /v1/chat/completions (Caused by NewConnectionError('<urllib3.connection.HTTPConnection object at 0x000002CBBF53FDF0>: Failed to establish a new connection: [WinError 10061] No connection could be made because the target machine actively refused it'))
ERROR    src.vision.vhs_vision:vhs_vision.py:246 API error processing region: cannot access local variable 'response' where it is not associated with a value
ERROR    src.vision.vhs_vision:vhs_vision.py:212 API request failed: HTTPConnectionPool(host='127.0.0.1', port=1234): Max retries exceeded with url: /v1/chat/completions (Caused by NewConnectionError('<urllib3.connection.HTTPConnection object at 0x000002CBBF53F790>: Failed to establish a new connection: [WinError 10061] No connection could be made because the target machine actively refused it'))
ERROR    src.vision.vhs_vision:vhs_vision.py:246 API error processing region: cannot access local variable 'response' where it is not associated with a value
ERROR    src.vision.vhs_vision:vhs_vision.py:212 API request failed: HTTPConnectionPool(host='127.0.0.1', port=1234): Max retries exceeded with url: /v1/chat/completions (Caused by NewConnectionError('<urllib3.connection.HTTPConnection object at 0x000002CBBF53F9B0>: Failed to establish a new connection: [WinError 10061] No connection could be made because the target machine actively refused it'))
ERROR    src.vision.vhs_vision:vhs_vision.py:246 API error processing region: cannot access local variable 'response' where it is not associated with a value
ERROR    src.vision.vhs_vision:vhs_vision.py:212 API request failed: HTTPConnectionPool(host='127.0.0.1', port=1234): Max retries exceeded with url: /v1/chat/completions (Caused by NewConnectionError('<urllib3.connection.HTTPConnection object at 0x000002CBC069D040>: Failed to establish a new connection: [WinError 10061] No connection could be made because the target machine actively refused it'))
ERROR    src.vision.vhs_vision:vhs_vision.py:246 API error processing region: cannot access local variable 'response' where it is not associated with a value
ERROR    src.vision.vhs_vision:vhs_vision.py:212 API request failed: HTTPConnectionPool(host='127.0.0.1', port=1234): Max retries exceeded with url: /v1/chat/completions (Caused by NewConnectionError('<urllib3.connection.HTTPConnection object at 0x000002CBC069C7C0>: Failed to establish a new connection: [WinError 10061] No connection could be made because the target machine actively refused it'))
ERROR    src.vision.vhs_vision:vhs_vision.py:246 API error processing region: cannot access local variable 'response' where it is not associated with a value
ERROR    src.vision.vhs_vision:vhs_vision.py:212 API request failed: HTTPConnectionPool(host='127.0.0.1', port=1234): Max retries exceeded with url: /v1/chat/completions (Caused by NewConnectionError('<urllib3.connection.HTTPConnection object at 0x000002CBC069D150>: Failed to establish a new connection: [WinError 10061] No connection could be made because the target machine actively refused it'))
ERROR    src.vision.vhs_vision:vhs_vision.py:246 API error processing region: cannot access local variable 'response' where it is not associated with a value
ERROR    src.vision.vhs_vision:vhs_vision.py:212 API request failed: HTTPConnectionPool(host='127.0.0.1', port=1234): Max retries exceeded with url: /v1/chat/completions (Caused by NewConnectionError('<urllib3.connection.HTTPConnection object at 0x000002CBC069C490>: Failed to establish a new connection: [WinError 10061] No connection could be made because the target machine actively refused it'))
ERROR    src.vision.vhs_vision:vhs_vision.py:246 API error processing region: cannot access local variable 'response' where it is not associated with a value
============================ slowest 10 durations =============================
36.03s call     tests/test_vision_processor.py::test_api_backup_triggering
35.88s call     tests/test_vision_processor.py::test_process_image_progress_tracking
35.80s call     tests/test_vision_processor.py::test_process_image_handles_missing_callback
35.79s call     tests/test_vision_processor.py::test_process_image_success_validation
2.02s setup    tests/test_vision_processor.py::test_process_image_progress_tracking
2.02s setup    tests/test_vision_processor.py::test_api_backup_triggering
2.01s setup    tests/test_vision_processor.py::test_process_image_success_validation
2.01s setup    tests/test_vision_processor.py::test_process_image_error_handling
2.01s setup    tests/test_vision_processor.py::test_process_image_with_invalid_image
2.01s setup    tests/test_vision_processor.py::test_process_image_handles_missing_callback
=========================== short test summary info ===========================
FAILED tests/test_opencv_utils.py::test_denoise_image - assert 0.0 < 0.0
 +  where 0.0 = <function std at 0x000002CBBC2DE1F0>(array([[255, 255, 255, ..., 255, 255, 255],\n       [255, 255, 255, ..., 255, 255, 255],\n       [255, 255, 255, ..., 255, 255, 255],\n       ...,\n       [255, 255, 255, ..., 255, 255, 255],\n       [255, 255, 255, ..., 255, 255, 255],\n       [255, 255, 255, ..., 255, 255, 255]], dtype=uint8))
 +    where <function std at 0x000002CBBC2DE1F0> = np.std
 +  and   0.0 = <function std at 0x000002CBBC2DE1F0>(array([[255, 255, 255, ..., 255, 255, 255],\n       [255, 255, 255, ..., 255, 255, 255],\n       [255, 255, 255, ..., 255, 255, 255],\n       ...,\n       [255, 255, 255, ..., 255, 255, 255],\n       [255, 255, 255, ..., 255, 255, 255],\n       [255, 255, 255, ..., 255, 255, 255]], dtype=uint8))
 +    where <function std at 0x000002CBBC2DE1F0> = np.std
FAILED tests/test_vision_processor.py::test_api_backup_triggering - assert False
 +  where False = any(<generator object test_api_backup_triggering.<locals>.<genexpr> at 0x000002CBC069AA80>)
=========== 2 failed, 21 passed, 50 deselected in 156.66s (0:02:36) ===========

================================================================================
