================================================================================
Image Processing System Test Report
Generated: 2025-03-03 06:05:02
================================================================================


UNIT_TESTS
----------
Duration: 157.83 seconds
Status: FAILED

Standard Output:
============================= test session starts =============================
platform win32 -- Python 3.13.2, pytest-8.3.4, pluggy-1.5.0 -- C:\Users\Noah\AppData\Local\Programs\Python\Python313\python.exe
cachedir: .pytest_cache
PyQt6 6.8.1 -- Qt runtime 6.8.2 -- Qt compiled 6.8.2
rootdir: C:\Users\Noah\Desktop\Ebay Auto
configfile: pytest.ini
testpaths: tests
plugins: anyio-4.8.0, asyncio-0.25.3, cov-6.0.0, mock-3.14.0, qt-4.4.0
asyncio: mode=Mode.AUTO, asyncio_default_fixture_loop_scope=function
collecting ... collected 73 items / 50 deselected / 23 selected

tests/test_opencv_utils.py::test_load_image_success PASSED               [  4%]
tests/test_opencv_utils.py::test_load_image_nonexistent 
-------------------------------- live log call --------------------------------
2025-03-03 06:02:27 [   ERROR] Failed to load image: nonexistent.jpg (opencv_utils.py:26)
PASSED                                                                   [  8%]
tests/test_opencv_utils.py::test_convert_to_grayscale_rgb PASSED         [ 13%]
tests/test_opencv_utils.py::test_convert_to_grayscale_already_gray PASSED [ 17%]
tests/test_opencv_utils.py::test_resize_image_larger PASSED              [ 21%]
tests/test_opencv_utils.py::test_resize_image_smaller PASSED             [ 26%]
tests/test_opencv_utils.py::test_enhance_contrast PASSED                 [ 30%]
tests/test_opencv_utils.py::test_denoise_image FAILED                    [ 34%]
tests/test_opencv_utils.py::test_preprocess_image_complete PASSED        [ 39%]
tests/test_opencv_utils.py::test_normalize_image PASSED                  [ 43%]
tests/test_opencv_utils.py::test_extract_text_regions PASSED             [ 47%]
tests/test_opencv_utils.py::test_error_handling 
-------------------------------- live log call --------------------------------
2025-03-03 06:02:27 [   ERROR] Contrast enhancement error: OpenCV(4.11.0) D:\a\opencv-python\opencv-python\opencv\modules\imgproc\src\clahe.cpp:353: error: (-215:Assertion failed) _src.type() == CV_8UC1 || _src.type() == CV_16UC1 in function '`anonymous-namespace'::CLAHE_Impl::apply'
 (opencv_utils.py:76)
2025-03-03 06:02:27 [   ERROR] Denoising error: divide by zero encountered in divide (opencv_utils.py:119)
2025-03-03 06:02:27 [   ERROR] Normalization error: divide by zero encountered in divide (opencv_utils.py:177)
PASSED                                                                   [ 52%]
tests/test_tmdb.py::test_search_movies PASSED                            [ 56%]
tests/test_tmdb.py::test_get_movie PASSED                                [ 60%]
tests/test_tmdb.py::test_invalid_movie_search PASSED                     [ 65%]
tests/test_tmdb.py::test_invalid_movie_id PASSED                         [ 69%]
tests/test_tmdb.py::test_tmdb_client_no_api_key PASSED                   [ 73%]
tests/test_vision_processor.py::test_process_image_progress_tracking 
------------------------------- live log setup --------------------------------
2025-03-03 06:02:29 [ WARNING] Error checking models: HTTPConnectionPool(host='127.0.0.1', port=1234): Max retries exceeded with url: /v1/models (Caused by ConnectTimeoutError(<urllib3.connection.HTTPConnection object at 0x0000028C953478C0>, 'Connection to 127.0.0.1 timed out. (connect timeout=2)')) (vhs_vision.py:64)
2025-03-03 06:02:29 [ WARNING] Discogs API not available - will rely on vision only (processor.py:39)
-------------------------------- live log call --------------------------------
2025-03-03 06:02:29 [    INFO] Processing image: C:\Users\Noah\AppData\Local\Temp\pytest-of-Noah\pytest-366\test_process_image_progress_tr0\test_vhs.jpg (processor.py:52)
2025-03-03 06:02:34 [   ERROR] API request failed: HTTPConnectionPool(host='127.0.0.1', port=1234): Max retries exceeded with url: /v1/chat/completions (Caused by NewConnectionError('<urllib3.connection.HTTPConnection object at 0x0000028C95494910>: Failed to establish a new connection: [WinError 10061] No connection could be made because the target machine actively refused it')) (vhs_vision.py:212)
2025-03-03 06:02:34 [   ERROR] API error processing region: cannot access local variable 'response' where it is not associated with a value (vhs_vision.py:246)
2025-03-03 06:02:39 [   ERROR] API request failed: HTTPConnectionPool(host='127.0.0.1', port=1234): Max retries exceeded with url: /v1/chat/completions (Caused by NewConnectionError('<urllib3.connection.HTTPConnection object at 0x0000028C95397360>: Failed to establish a new connection: [WinError 10061] No connection could be made because the target machine actively refused it')) (vhs_vision.py:212)
2025-03-03 06:02:39 [   ERROR] API error processing region: cannot access local variable 'response' where it is not associated with a value (vhs_vision.py:246)
2025-03-03 06:02:44 [   ERROR] API request failed: HTTPConnectionPool(host='127.0.0.1', port=1234): Max retries exceeded with url: /v1/chat/completions (Caused by NewConnectionError('<urllib3.connection.HTTPConnection object at 0x0000028C964919D0>: Failed to establish a new connection: [WinError 10061] No connection could be made because the target machine actively refused it')) (vhs_vision.py:212)
2025-03-03 06:02:44 [   ERROR] API error processing region: cannot access local variable 'response' where it is not associated with a value (vhs_vision.py:246)
2025-03-03 06:02:49 [   ERROR] API request failed: HTTPConnectionPool(host='127.0.0.1', port=1234): Max retries exceeded with url: /v1/chat/completions (Caused by NewConnectionError('<urllib3.connection.HTTPConnection object at 0x0000028C96492580>: Failed to establish a new connection: [WinError 10061] No connection could be made because the target machine actively refused it')) (vhs_vision.py:212)
2025-03-03 06:02:49 [   ERROR] API error processing region: cannot access local variable 'response' where it is not associated with a value (vhs_vision.py:246)
2025-03-03 06:02:55 [   ERROR] API request failed: HTTPConnectionPool(host='127.0.0.1', port=1234): Max retries exceeded with url: /v1/chat/completions (Caused by NewConnectionError('<urllib3.connection.HTTPConnection object at 0x0000028C96492BE0>: Failed to establish a new connection: [WinError 10061] No connection could be made because the target machine actively refused it')) (vhs_vision.py:212)
2025-03-03 06:02:55 [   ERROR] API error processing region: cannot access local variable 'response' where it is not associated with a value (vhs_vision.py:246)
2025-03-03 06:03:00 [   ERROR] API request failed: HTTPConnectionPool(host='127.0.0.1', port=1234): Max retries exceeded with url: /v1/chat/completions (Caused by NewConnectionError('<urllib3.connection.HTTPConnection object at 0x0000028C9534BF00>: Failed to establish a new connection: [WinError 10061] No connection could be made because the target machine actively refused it')) (vhs_vision.py:212)
2025-03-03 06:03:00 [   ERROR] API error processing region: cannot access local variable 'response' where it is not associated with a value (vhs_vision.py:246)
2025-03-03 06:03:05 [   ERROR] API request failed: HTTPConnectionPool(host='127.0.0.1', port=1234): Max retries exceeded with url: /v1/chat/completions (Caused by NewConnectionError('<urllib3.connection.HTTPConnection object at 0x0000028C96492CF0>: Failed to establish a new connection: [WinError 10061] No connection could be made because the target machine actively refused it')) (vhs_vision.py:212)
2025-03-03 06:03:05 [   ERROR] API error processing region: cannot access local variable 'response' where it is not associated with a value (vhs_vision.py:246)
PASSED                                                                   [ 78%]
tests/test_vision_processor.py::test_process_image_handles_missing_callback 
------------------------------- live log setup --------------------------------
2025-03-03 06:03:07 [ WARNING] Error checking models: HTTPConnectionPool(host='127.0.0.1', port=1234): Max retries exceeded with url: /v1/models (Caused by ConnectTimeoutError(<urllib3.connection.HTTPConnection object at 0x0000028C9534BAC0>, 'Connection to 127.0.0.1 timed out. (connect timeout=2)')) (vhs_vision.py:64)
2025-03-03 06:03:07 [ WARNING] Discogs API not available - will rely on vision only (processor.py:39)
-------------------------------- live log call --------------------------------
2025-03-03 06:03:07 [    INFO] Processing image: C:\Users\Noah\AppData\Local\Temp\pytest-of-Noah\pytest-366\test_process_image_handles_mis0\test_vhs.jpg (processor.py:52)
2025-03-03 06:03:12 [   ERROR] API request failed: HTTPConnectionPool(host='127.0.0.1', port=1234): Max retries exceeded with url: /v1/chat/completions (Caused by NewConnectionError('<urllib3.connection.HTTPConnection object at 0x0000028C96492E00>: Failed to establish a new connection: [WinError 10061] No connection could be made because the target machine actively refused it')) (vhs_vision.py:212)
2025-03-03 06:03:12 [   ERROR] API error processing region: cannot access local variable 'response' where it is not associated with a value (vhs_vision.py:246)
2025-03-03 06:03:17 [   ERROR] API request failed: HTTPConnectionPool(host='127.0.0.1', port=1234): Max retries exceeded with url: /v1/chat/completions (Caused by NewConnectionError('<urllib3.connection.HTTPConnection object at 0x0000028C96492140>: Failed to establish a new connection: [WinError 10061] No connection could be made because the target machine actively refused it')) (vhs_vision.py:212)
2025-03-03 06:03:17 [   ERROR] API error processing region: cannot access local variable 'response' where it is not associated with a value (vhs_vision.py:246)
2025-03-03 06:03:22 [   ERROR] API request failed: HTTPConnectionPool(host='127.0.0.1', port=1234): Max retries exceeded with url: /v1/chat/completions (Caused by NewConnectionError('<urllib3.connection.HTTPConnection object at 0x0000028C96491590>: Failed to establish a new connection: [WinError 10061] No connection could be made because the target machine actively refused it')) (vhs_vision.py:212)
2025-03-03 06:03:22 [   ERROR] API error processing region: cannot access local variable 'response' where it is not associated with a value (vhs_vision.py:246)
2025-03-03 06:03:27 [   ERROR] API request failed: HTTPConnectionPool(host='127.0.0.1', port=1234): Max retries exceeded with url: /v1/chat/completions (Caused by NewConnectionError('<urllib3.connection.HTTPConnection object at 0x0000028C96491040>: Failed to establish a new connection: [WinError 10061] No connection could be made because the target machine actively refused it')) (vhs_vision.py:212)
2025-03-03 06:03:27 [   ERROR] API error processing region: cannot access local variable 'response' where it is not associated with a value (vhs_vision.py:246)
2025-03-03 06:03:32 [   ERROR] API request failed: HTTPConnectionPool(host='127.0.0.1', port=1234): Max retries exceeded with url: /v1/chat/completions (Caused by NewConnectionError('<urllib3.connection.HTTPConnection object at 0x0000028C9534B8A0>: Failed to establish a new connection: [WinError 10061] No connection could be made because the target machine actively refused it')) (vhs_vision.py:212)
2025-03-03 06:03:32 [   ERROR] API error processing region: cannot access local variable 'response' where it is not associated with a value (vhs_vision.py:246)
2025-03-03 06:03:37 [   ERROR] API request failed: HTTPConnectionPool(host='127.0.0.1', port=1234): Max retries exceeded with url: /v1/chat/completions (Caused by NewConnectionError('<urllib3.connection.HTTPConnection object at 0x0000028C9534B570>: Failed to establish a new connection: [WinError 10061] No connection could be made because the target machine actively refused it')) (vhs_vision.py:212)
2025-03-03 06:03:37 [   ERROR] API error processing region: cannot access local variable 'response' where it is not associated with a value (vhs_vision.py:246)
2025-03-03 06:03:43 [   ERROR] API request failed: HTTPConnectionPool(host='127.0.0.1', port=1234): Max retries exceeded with url: /v1/chat/completions (Caused by NewConnectionError('<urllib3.connection.HTTPConnection object at 0x0000028C96490E20>: Failed to establish a new connection: [WinError 10061] No connection could be made because the target machine actively refused it')) (vhs_vision.py:212)
2025-03-03 06:03:43 [   ERROR] API error processing region: cannot access local variable 'response' where it is not associated with a value (vhs_vision.py:246)
PASSED                                                                   [ 82%]
tests/test_vision_processor.py::test_process_image_error_handling 
------------------------------- live log setup --------------------------------
2025-03-03 06:03:45 [ WARNING] Error checking models: HTTPConnectionPool(host='127.0.0.1', port=1234): Max retries exceeded with url: /v1/models (Caused by ConnectTimeoutError(<urllib3.connection.HTTPConnection object at 0x0000028C9534BBD0>, 'Connection to 127.0.0.1 timed out. (connect timeout=2)')) (vhs_vision.py:64)
2025-03-03 06:03:45 [ WARNING] Discogs API not available - will rely on vision only (processor.py:39)
-------------------------------- live log call --------------------------------
2025-03-03 06:03:45 [    INFO] Processing image: nonexistent.jpg (processor.py:52)
2025-03-03 06:03:45 [   ERROR] Failed to load image: nonexistent.jpg (opencv_utils.py:26)
PASSED                                                                   [ 86%]
tests/test_vision_processor.py::test_process_image_with_invalid_image 
------------------------------- live log setup --------------------------------
2025-03-03 06:03:47 [ WARNING] Error checking models: HTTPConnectionPool(host='127.0.0.1', port=1234): Max retries exceeded with url: /v1/models (Caused by ConnectTimeoutError(<urllib3.connection.HTTPConnection object at 0x0000028C96492470>, 'Connection to 127.0.0.1 timed out. (connect timeout=2)')) (vhs_vision.py:64)
2025-03-03 06:03:47 [ WARNING] Discogs API not available - will rely on vision only (processor.py:39)
-------------------------------- live log call --------------------------------
2025-03-03 06:03:47 [    INFO] Processing image: C:\Users\Noah\AppData\Local\Temp\pytest-of-Noah\pytest-366\test_process_image_with_invali0\invalid.jpg (processor.py:52)
2025-03-03 06:03:47 [   ERROR] Failed to load image: C:\Users\Noah\AppData\Local\Temp\pytest-of-Noah\pytest-366\test_process_image_with_invali0\invalid.jpg (opencv_utils.py:26)
PASSED                                                                   [ 91%]
tests/test_vision_processor.py::test_process_image_success_validation 
------------------------------- live log setup --------------------------------
2025-03-03 06:03:49 [ WARNING] Error checking models: HTTPConnectionPool(host='127.0.0.1', port=1234): Max retries exceeded with url: /v1/models (Caused by ConnectTimeoutError(<urllib3.connection.HTTPConnection object at 0x0000028C96490AF0>, 'Connection to 127.0.0.1 timed out. (connect timeout=2)')) (vhs_vision.py:64)
2025-03-03 06:03:49 [ WARNING] Discogs API not available - will rely on vision only (processor.py:39)
-------------------------------- live log call --------------------------------
2025-03-03 06:03:49 [    INFO] Processing image: C:\Users\Noah\AppData\Local\Temp\pytest-of-Noah\pytest-366\test_process_image_success_val0\test_vhs.jpg (processor.py:52)
2025-03-03 06:03:54 [   ERROR] API request failed: HTTPConnectionPool(host='127.0.0.1', port=1234): Max retries exceeded with url: /v1/chat/completions (Caused by NewConnectionError('<urllib3.connection.HTTPConnection object at 0x0000028C96492030>: Failed to establish a new connection: [WinError 10061] No connection could be made because the target machine actively refused it')) (vhs_vision.py:212)
2025-03-03 06:03:54 [   ERROR] API error processing region: cannot access local variable 'response' where it is not associated with a value (vhs_vision.py:246)
2025-03-03 06:03:59 [   ERROR] API request failed: HTTPConnectionPool(host='127.0.0.1', port=1234): Max retries exceeded with url: /v1/chat/completions (Caused by NewConnectionError('<urllib3.connection.HTTPConnection object at 0x0000028C964928B0>: Failed to establish a new connection: [WinError 10061] No connection could be made because the target machine actively refused it')) (vhs_vision.py:212)
2025-03-03 06:03:59 [   ERROR] API error processing region: cannot access local variable 'response' where it is not associated with a value (vhs_vision.py:246)
2025-03-03 06:04:04 [   ERROR] API request failed: HTTPConnectionPool(host='127.0.0.1', port=1234): Max retries exceeded with url: /v1/chat/completions (Caused by NewConnectionError('<urllib3.connection.HTTPConnection object at 0x0000028C9534BBD0>: Failed to establish a new connection: [WinError 10061] No connection could be made because the target machine actively refused it')) (vhs_vision.py:212)
2025-03-03 06:04:04 [   ERROR] API error processing region: cannot access local variable 'response' where it is not associated with a value (vhs_vision.py:246)
2025-03-03 06:04:09 [   ERROR] API request failed: HTTPConnectionPool(host='127.0.0.1', port=1234): Max retries exceeded with url: /v1/chat/completions (Caused by NewConnectionError('<urllib3.connection.HTTPConnection object at 0x0000028C9534A7A0>: Failed to establish a new connection: [WinError 10061] No connection could be made because the target machine actively refused it')) (vhs_vision.py:212)
2025-03-03 06:04:09 [   ERROR] API error processing region: cannot access local variable 'response' where it is not associated with a value (vhs_vision.py:246)
2025-03-03 06:04:14 [   ERROR] API request failed: HTTPConnectionPool(host='127.0.0.1', port=1234): Max retries exceeded with url: /v1/chat/completions (Caused by NewConnectionError('<urllib3.connection.HTTPConnection object at 0x0000028C964927A0>: Failed to establish a new connection: [WinError 10061] No connection could be made because the target machine actively refused it')) (vhs_vision.py:212)
2025-03-03 06:04:14 [   ERROR] API error processing region: cannot access local variable 'response' where it is not associated with a value (vhs_vision.py:246)
2025-03-03 06:04:19 [   ERROR] API request failed: HTTPConnectionPool(host='127.0.0.1', port=1234): Max retries exceeded with url: /v1/chat/completions (Caused by NewConnectionError('<urllib3.connection.HTTPConnection object at 0x0000028C96491AE0>: Failed to establish a new connection: [WinError 10061] No connection could be made because the target machine actively refused it')) (vhs_vision.py:212)
2025-03-03 06:04:19 [   ERROR] API error processing region: cannot access local variable 'response' where it is not associated with a value (vhs_vision.py:246)
2025-03-03 06:04:24 [   ERROR] API request failed: HTTPConnectionPool(host='127.0.0.1', port=1234): Max retries exceeded with url: /v1/chat/completions (Caused by NewConnectionError('<urllib3.connection.HTTPConnection object at 0x0000028C96492470>: Failed to establish a new connection: [WinError 10061] No connection could be made because the target machine actively refused it')) (vhs_vision.py:212)
2025-03-03 06:04:24 [   ERROR] API error processing region: cannot access local variable 'response' where it is not associated with a value (vhs_vision.py:246)
PASSED                                                                   [ 95%]
tests/test_vision_processor.py::test_api_backup_triggering 
------------------------------- live log setup --------------------------------
2025-03-03 06:04:26 [ WARNING] Error checking models: HTTPConnectionPool(host='127.0.0.1', port=1234): Max retries exceeded with url: /v1/models (Caused by ConnectTimeoutError(<urllib3.connection.HTTPConnection object at 0x0000028C9534BAC0>, 'Connection to 127.0.0.1 timed out. (connect timeout=2)')) (vhs_vision.py:64)
2025-03-03 06:04:26 [ WARNING] Discogs API not available - will rely on vision only (processor.py:39)
-------------------------------- live log call --------------------------------
2025-03-03 06:04:26 [    INFO] Processing image: C:\Users\Noah\AppData\Local\Temp\pytest-of-Noah\pytest-366\test_api_backup_triggering0\test_vhs.jpg (processor.py:52)
2025-03-03 06:04:32 [   ERROR] API request failed: HTTPConnectionPool(host='127.0.0.1', port=1234): Max retries exceeded with url: /v1/chat/completions (Caused by NewConnectionError('<urllib3.connection.HTTPConnection object at 0x0000028C96492140>: Failed to establish a new connection: [WinError 10061] No connection could be made because the target machine actively refused it')) (vhs_vision.py:212)
2025-03-03 06:04:32 [   ERROR] API error processing region: cannot access local variable 'response' where it is not associated with a value (vhs_vision.py:246)
2025-03-03 06:04:37 [   ERROR] API request failed: HTTPConnectionPool(host='127.0.0.1', port=1234): Max retries exceeded with url: /v1/chat/completions (Caused by NewConnectionError('<urllib3.connection.HTTPConnection object at 0x0000028C9534BCE0>: Failed to establish a new connection: [WinError 10061] No connection could be made because the target machine actively refused it')) (vhs_vision.py:212)
2025-03-03 06:04:37 [   ERROR] API error processing region: cannot access local variable 'response' where it is not associated with a value (vhs_vision.py:246)
2025-03-03 06:04:42 [   ERROR] API request failed: HTTPConnectionPool(host='127.0.0.1', port=1234): Max retries exceeded with url: /v1/chat/completions (Caused by NewConnectionError('<urllib3.connection.HTTPConnection object at 0x0000028C9534BBD0>: Failed to establish a new connection: [WinError 10061] No connection could be made because the target machine actively refused it')) (vhs_vision.py:212)
2025-03-03 06:04:42 [   ERROR] API error processing region: cannot access local variable 'response' where it is not associated with a value (vhs_vision.py:246)
2025-03-03 06:04:47 [   ERROR] API request failed: HTTPConnectionPool(host='127.0.0.1', port=1234): Max retries exceeded with url: /v1/chat/completions (Caused by NewConnectionError('<urllib3.connection.HTTPConnection object at 0x0000028C96492140>: Failed to establish a new connection: [WinError 10061] No connection could be made because the target machine actively refused it')) (vhs_vision.py:212)
2025-03-03 06:04:47 [   ERROR] API error processing region: cannot access local variable 'response' where it is not associated with a value (vhs_vision.py:246)
2025-03-03 06:04:52 [   ERROR] API request failed: HTTPConnectionPool(host='127.0.0.1', port=1234): Max retries exceeded with url: /v1/chat/completions (Caused by NewConnectionError('<urllib3.connection.HTTPConnection object at 0x0000028C964918C0>: Failed to establish a new connection: [WinError 10061] No connection could be made because the target machine actively refused it')) (vhs_vision.py:212)
2025-03-03 06:04:52 [   ERROR] API error processing region: cannot access local variable 'response' where it is not associated with a value (vhs_vision.py:246)
2025-03-03 06:04:57 [   ERROR] API request failed: HTTPConnectionPool(host='127.0.0.1', port=1234): Max retries exceeded with url: /v1/chat/completions (Caused by NewConnectionError('<urllib3.connection.HTTPConnection object at 0x0000028C96492580>: Failed to establish a new connection: [WinError 10061] No connection could be made because the target machine actively refused it')) (vhs_vision.py:212)
2025-03-03 06:04:57 [   ERROR] API error processing region: cannot access local variable 'response' where it is not associated with a value (vhs_vision.py:246)
2025-03-03 06:05:02 [   ERROR] API request failed: HTTPConnectionPool(host='127.0.0.1', port=1234): Max retries exceeded with url: /v1/chat/completions (Caused by NewConnectionError('<urllib3.connection.HTTPConnection object at 0x0000028C96492030>: Failed to establish a new connection: [WinError 10061] No connection could be made because the target machine actively refused it')) (vhs_vision.py:212)
2025-03-03 06:05:02 [   ERROR] API error processing region: cannot access local variable 'response' where it is not associated with a value (vhs_vision.py:246)
FAILED                                                                   [100%]

================================== FAILURES ===================================
_____________________________ test_denoise_image ______________________________

noisy_image = array([[  1, 205,  27, ..., 241, 232,  15],
       [  8,  12, 226, ..., 236,  15,  13],
       [ 20, 252,  15, ...,   ..., 245,   1,  41],
       [ 19,  40,  21, ...,  26,  39, 251],
       [241,  13,  32, ...,  30, 214, 240]], dtype=uint8)

    @pytest.mark.unit
    def test_denoise_image(noisy_image):
        """Test image denoising."""
        denoised = opencv_utils.denoise_image(noisy_image)
    
        # Denoised image should have less variation in flat areas
        roi_noisy = noisy_image[30:70, 30:70]  # Center region
        roi_denoised = denoised[30:70, 30:70]
>       assert np.std(roi_denoised) < np.std(roi_noisy)
E       assert 0.0 < 0.0
E        +  where 0.0 = <function std at 0x0000028C920FE1B0>(array([[255, 255, 255, ..., 255, 255, 255],\n       [255, 255, 255, ..., 255, 255, 255],\n       [255, 255, 255, ..., 255, 255, 255],\n       ...,\n       [255, 255, 255, ..., 255, 255, 255],\n       [255, 255, 255, ..., 255, 255, 255],\n       [255, 255, 255, ..., 255, 255, 255]], dtype=uint8))
E        +    where <function std at 0x0000028C920FE1B0> = np.std
E        +  and   0.0 = <function std at 0x0000028C920FE1B0>(array([[255, 255, 255, ..., 255, 255, 255],\n       [255, 255, 255, ..., 255, 255, 255],\n       [255, 255, 255, ..., 255, 255, 255],\n       ...,\n       [255, 255, 255, ..., 255, 255, 255],\n       [255, 255, 255, ..., 255, 255, 255],\n       [255, 255, 255, ..., 255, 255, 255]], dtype=uint8))
E        +    where <function std at 0x0000028C920FE1B0> = np.std

tests\test_opencv_utils.py:101: AssertionError
_________________________ test_api_backup_triggering __________________________

processor = <src.vision.processor.VisionProcessor object at 0x0000028C95436570>
sample_vhs_image = 'C:\\Users\\Noah\\AppData\\Local\\Temp\\pytest-of-Noah\\pytest-366\\test_api_backup_triggering0\\test_vhs.jpg'
monkeypatch = <_pytest.monkeypatch.MonkeyPatch object at 0x0000028C95397230>

    @pytest.mark.unit
    def test_api_backup_triggering(processor, sample_vhs_image, monkeypatch):
        """Test that API backup is triggered for low confidence results."""
        # Mock the _needs_api_backup method to always return True
        monkeypatch.setattr(processor, "_needs_api_backup", lambda x: True)
    
        # Create a mock for the API call
        mock_api_result = {
            "title": "API Title",
            "year": "2024",
            "runtime": "120",
            "confidence": 0.85
        }
        monkeypatch.setattr(
            "src.enrichment.api_client.search_movie_details",
            lambda x: mock_api_result
        )
    
        results = processor.process_image(sample_vhs_image)
    
        # Verify that API data was used
>       assert any(source == "api" for source in results.get("source", {}).values())
E       assert False
E        +  where False = any(<generator object test_api_backup_triggering.<locals>.<genexpr> at 0x0000028C964C9080>)

tests\test_vision_processor.py:157: AssertionError
----------------------------- Captured log setup ------------------------------
WARNING  src.vision.vhs_vision:vhs_vision.py:64 Error checking models: HTTPConnectionPool(host='127.0.0.1', port=1234): Max retries exceeded with url: /v1/models (Caused by ConnectTimeoutError(<urllib3.connection.HTTPConnection object at 0x0000028C9534BAC0>, 'Connection to 127.0.0.1 timed out. (connect timeout=2)'))
WARNING  src.vision.processor:processor.py:39 Discogs API not available - will rely on vision only
------------------------------ Captured log call ------------------------------
INFO     src.vision.processor:processor.py:52 Processing image: C:\Users\Noah\AppData\Local\Temp\pytest-of-Noah\pytest-366\test_api_backup_triggering0\test_vhs.jpg
ERROR    src.vision.vhs_vision:vhs_vision.py:212 API request failed: HTTPConnectionPool(host='127.0.0.1', port=1234): Max retries exceeded with url: /v1/chat/completions (Caused by NewConnectionError('<urllib3.connection.HTTPConnection object at 0x0000028C96492140>: Failed to establish a new connection: [WinError 10061] No connection could be made because the target machine actively refused it'))
ERROR    src.vision.vhs_vision:vhs_vision.py:246 API error processing region: cannot access local variable 'response' where it is not associated with a value
ERROR    src.vision.vhs_vision:vhs_vision.py:212 API request failed: HTTPConnectionPool(host='127.0.0.1', port=1234): Max retries exceeded with url: /v1/chat/completions (Caused by NewConnectionError('<urllib3.connection.HTTPConnection object at 0x0000028C9534BCE0>: Failed to establish a new connection: [WinError 10061] No connection could be made because the target machine actively refused it'))
ERROR    src.vision.vhs_vision:vhs_vision.py:246 API error processing region: cannot access local variable 'response' where it is not associated with a value
ERROR    src.vision.vhs_vision:vhs_vision.py:212 API request failed: HTTPConnectionPool(host='127.0.0.1', port=1234): Max retries exceeded with url: /v1/chat/completions (Caused by NewConnectionError('<urllib3.connection.HTTPConnection object at 0x0000028C9534BBD0>: Failed to establish a new connection: [WinError 10061] No connection could be made because the target machine actively refused it'))
ERROR    src.vision.vhs_vision:vhs_vision.py:246 API error processing region: cannot access local variable 'response' where it is not associated with a value
ERROR    src.vision.vhs_vision:vhs_vision.py:212 API request failed: HTTPConnectionPool(host='127.0.0.1', port=1234): Max retries exceeded with url: /v1/chat/completions (Caused by NewConnectionError('<urllib3.connection.HTTPConnection object at 0x0000028C96492140>: Failed to establish a new connection: [WinError 10061] No connection could be made because the target machine actively refused it'))
ERROR    src.vision.vhs_vision:vhs_vision.py:246 API error processing region: cannot access local variable 'response' where it is not associated with a value
ERROR    src.vision.vhs_vision:vhs_vision.py:212 API request failed: HTTPConnectionPool(host='127.0.0.1', port=1234): Max retries exceeded with url: /v1/chat/completions (Caused by NewConnectionError('<urllib3.connection.HTTPConnection object at 0x0000028C964918C0>: Failed to establish a new connection: [WinError 10061] No connection could be made because the target machine actively refused it'))
ERROR    src.vision.vhs_vision:vhs_vision.py:246 API error processing region: cannot access local variable 'response' where it is not associated with a value
ERROR    src.vision.vhs_vision:vhs_vision.py:212 API request failed: HTTPConnectionPool(host='127.0.0.1', port=1234): Max retries exceeded with url: /v1/chat/completions (Caused by NewConnectionError('<urllib3.connection.HTTPConnection object at 0x0000028C96492580>: Failed to establish a new connection: [WinError 10061] No connection could be made because the target machine actively refused it'))
ERROR    src.vision.vhs_vision:vhs_vision.py:246 API error processing region: cannot access local variable 'response' where it is not associated with a value
ERROR    src.vision.vhs_vision:vhs_vision.py:212 API request failed: HTTPConnectionPool(host='127.0.0.1', port=1234): Max retries exceeded with url: /v1/chat/completions (Caused by NewConnectionError('<urllib3.connection.HTTPConnection object at 0x0000028C96492030>: Failed to establish a new connection: [WinError 10061] No connection could be made because the target machine actively refused it'))
ERROR    src.vision.vhs_vision:vhs_vision.py:246 API error processing region: cannot access local variable 'response' where it is not associated with a value
============================ slowest 10 durations =============================
35.81s call     tests/test_vision_processor.py::test_process_image_progress_tracking
35.79s call     tests/test_vision_processor.py::test_process_image_success_validation
35.77s call     tests/test_vision_processor.py::test_process_image_handles_missing_callback
35.74s call     tests/test_vision_processor.py::test_api_backup_triggering
2.02s setup    tests/test_vision_processor.py::test_process_image_progress_tracking
2.01s setup    tests/test_vision_processor.py::test_api_backup_triggering
2.01s setup    tests/test_vision_processor.py::test_process_image_with_invalid_image
2.01s setup    tests/test_vision_processor.py::test_process_image_success_validation
2.00s setup    tests/test_vision_processor.py::test_process_image_handles_missing_callback
2.00s setup    tests/test_vision_processor.py::test_process_image_error_handling
=========================== short test summary info ===========================
FAILED tests/test_opencv_utils.py::test_denoise_image - assert 0.0 < 0.0
 +  where 0.0 = <function std at 0x0000028C920FE1B0>(array([[255, 255, 255, ..., 255, 255, 255],\n       [255, 255, 255, ..., 255, 255, 255],\n       [255, 255, 255, ..., 255, 255, 255],\n       ...,\n       [255, 255, 255, ..., 255, 255, 255],\n       [255, 255, 255, ..., 255, 255, 255],\n       [255, 255, 255, ..., 255, 255, 255]], dtype=uint8))
 +    where <function std at 0x0000028C920FE1B0> = np.std
 +  and   0.0 = <function std at 0x0000028C920FE1B0>(array([[255, 255, 255, ..., 255, 255, 255],\n       [255, 255, 255, ..., 255, 255, 255],\n       [255, 255, 255, ..., 255, 255, 255],\n       ...,\n       [255, 255, 255, ..., 255, 255, 255],\n       [255, 255, 255, ..., 255, 255, 255],\n       [255, 255, 255, ..., 255, 255, 255]], dtype=uint8))
 +    where <function std at 0x0000028C920FE1B0> = np.std
FAILED tests/test_vision_processor.py::test_api_backup_triggering - assert False
 +  where False = any(<generator object test_api_backup_triggering.<locals>.<genexpr> at 0x0000028C964C9080>)
=========== 2 failed, 21 passed, 50 deselected in 155.90s (0:02:35) ===========

================================================================================
